<?xml version="1.0" encoding="UTF-8"?>
<robot generated="20190827 14:16:46.805" generator="Robot 3.1.2 (Python 3.5.3 on win32)" rpa="false">
<suite name="Test" id="s1" source="D:\abobo_project\robot_project\test">
<suite name="Test01" id="s1-s1" source="D:\abobo_project\robot_project\test\test01.robot">
<test name="3" id="s1-s1-t1">
<kw name="Log" library="BuiltIn">
<doc>Logs the given message with the given level.</doc>
<arguments>
<arg>${gaga}</arg>
</arguments>
<msg level="INFO" timestamp="20190827 14:16:47.066">Brianggkggkk开外挂kkkkkkkkkkkkkk</msg>
<status starttime="20190827 14:16:47.066" status="PASS" endtime="20190827 14:16:47.066"></status>
</kw>
<status starttime="20190827 14:16:47.065" status="PASS" endtime="20190827 14:16:47.066" critical="yes"></status>
</test>
<status starttime="20190827 14:16:46.843" status="PASS" endtime="20190827 14:16:47.067"></status>
</suite>
<status starttime="20190827 14:16:46.823" status="PASS" endtime="20190827 14:16:47.067"></status>
</suite>
<statistics>
<total>
<stat fail="0" pass="1">Critical Tests</stat>
<stat fail="0" pass="1">All Tests</stat>
</total>
<tag>
</tag>
<suite>
<stat name="Test" id="s1" fail="0" pass="1">Test</stat>
<stat name="Test01" id="s1-s1" fail="0" pass="1">Test.Test01</stat>
</suite>
</statistics>
<errors>
<msg level="ERROR" timestamp="20190827 14:16:46.820">Taking listener 'D:\abobo_project\robot_project\venv\lib\site-packages\robotide\contrib\testrunner\TestRunnerAgent.py' into use failed: Importing listener 'D:\abobo_project\robot_project\venv\lib\site-packages\robotide\contrib\testrunner\TestRunnerAgent.py' failed: Creating instance failed: IndexError: tuple index out of range
Traceback (most recent call last):
  File "D:\abobo_project\robot_project\venv\lib\site-packages\robotide\contrib\testrunner\TestRunnerAgent.py", line 153, in __init__
    self.port = int(args[0])</msg>
</errors>
</robot>
